pytest~=7.4; python_version < '3.9'
pytest~=8.3; python_version >= '3.9'
pytest-asyncio~=0.21.2; python_version < '3.9'
pytest-asyncio~=0.25.3; python_version >= '3.9'
pytest-cov~=4.1; python_version < '3.9'
pytest-cov~=6.0; python_version >= '3.9'
pytest-xdist~=3.6
pytest-split~=0.10.0
pytest-mock~=3.14
pytest-timeout~=2.3
pytest-flakefinder~=1.1
pytest-memray~=1.7; sys_platform != 'win32'
pyfakefs~=5.7
parameterized~=0.9.0
Faker<35.0.0; python_version < '3.9'

flask~=2.2
fastapi~=0.115.3
httpx~=0.27.0
responses~=0.23.3
uvicorn~=0.32.0

pandas~=2.2; python_version >= '3.11'
numpy~=1.26; python_version >= '3.11'
pandas~=1.3; python_version < '3.11'
numpy~=1.24; python_version < '3.11'

coverage[toml]~=7.6

pyte~=0.8.1  # Terminal emulator for testing interactions with the terminal.

hypothesis<6.131.1
# Stopgap fix until we can resolve sys.modules-related error, inadvertently introduced by hypothesis==6.131.1.
# This manifests in CI as RuntimeErrors like:
#
#     .0 = <dict_valueiterator object at ...>
#
#         return tuple(
#             module
#     >       for module in sys.modules.values()
#             if (
#                 getattr(module, "__file__", None) is not None
#                 and _is_local_module_file(module.__file__)
#             )
#         )
#     E   RuntimeError: dictionary changed size during iteration
#
#     .../site-packages/hypothesis/internal/constants_ast.py:147: RuntimeError
hypothesis-fspaths
