2023-07-14 05:10:00,413 INFO    MainThread:56851 [wandb_setup.py:_flush():76] Current SDK version is 0.15.6.dev1
2023-07-14 05:10:00,413 INFO    MainThread:56851 [wandb_setup.py:_flush():76] Configure stats pid to 56851
2023-07-14 05:10:00,413 INFO    MainThread:56851 [wandb_setup.py:_flush():76] Loading settings from /Users/estellaxin/.config/wandb/settings
2023-07-14 05:10:00,413 INFO    MainThread:56851 [wandb_setup.py:_flush():76] Loading settings from /private/var/folders/vh/k98fyx251l792bbzj485tdnw0000gp/T/tmp89de1qar/wandb/settings
2023-07-14 05:10:00,413 WARNING MainThread:56851 [wandb_setup.py:_flush():76] Unknown environment variable: WANDB_ERROR_REPORTING
2023-07-14 05:10:00,413 WARNING MainThread:56851 [wandb_setup.py:_flush():76] Unknown environment variable: WANDB_ARTIFACTS
2023-07-14 05:10:00,413 WARNING MainThread:56851 [wandb_setup.py:_flush():76] Unknown environment variable: WANDB_CONFIG
2023-07-14 05:10:00,413 INFO    MainThread:56851 [wandb_setup.py:_flush():76] Loading settings from environment variables: {'_network_buffer': '1000', 'username': 'test_run_in_launch_context_with_artifact_string_no_used_as_env_var', 'base_url': 'http://localhost:55603', 'api_key': '***REDACTED***'}
2023-07-14 05:10:00,413 INFO    MainThread:56851 [wandb_setup.py:_flush():76] Applying setup settings: {'_disable_service': False}
2023-07-14 05:10:00,413 INFO    MainThread:56851 [wandb_setup.py:_flush():76] Inferring run settings from compute environment: {'program': '<python with no main file>'}
2023-07-14 05:10:00,413 INFO    MainThread:56851 [wandb_init.py:_log_setup():507] Logging user logs to /Users/estellaxin/Projects/wandb/tests/pytest_tests/unit_tests_old/logs/test_run_in_launch_context_with_artifact_string_no_used_as_env_var/wandb/run-20230714_051000-k00neduy/logs/debug.log
2023-07-14 05:10:00,413 INFO    MainThread:56851 [wandb_init.py:_log_setup():508] Logging internal logs to /Users/estellaxin/Projects/wandb/tests/pytest_tests/unit_tests_old/logs/test_run_in_launch_context_with_artifact_string_no_used_as_env_var/wandb/run-20230714_051000-k00neduy/logs/debug-internal.log
2023-07-14 05:10:00,413 INFO    MainThread:56851 [wandb_init.py:init():547] calling init triggers
2023-07-14 05:10:00,413 INFO    MainThread:56851 [wandb_init.py:init():554] wandb.init called with sweep_config: {}
config: {'epochs': 2, 'lr': 0.004}
2023-07-14 05:10:00,414 INFO    MainThread:56851 [wandb_init.py:init():596] starting backend
2023-07-14 05:10:00,414 INFO    MainThread:56851 [wandb_init.py:init():600] setting up manager
2023-07-14 05:10:00,417 INFO    MainThread:56851 [backend.py:_multiprocessing_setup():106] multiprocessing start_methods=spawn,fork,forkserver, using: spawn
2023-07-14 05:10:00,418 INFO    MainThread:56851 [wandb_init.py:init():606] backend started and connected
2023-07-14 05:10:00,419 INFO    MainThread:56851 [wandb_run.py:_config_callback():1282] config_cb None None {'epochs': 10}
2023-07-14 05:10:00,431 INFO    MainThread:56851 [wandb_init.py:init():697] updated telemetry
2023-07-14 05:10:00,432 INFO    MainThread:56851 [wandb_init.py:init():730] communicating run to backend with 60.0 second timeout
2023-07-14 05:10:00,473 INFO    MainThread:56851 [wandb_run.py:_on_init():2174] communicating current version
2023-07-14 05:10:01,783 INFO    MainThread:56851 [wandb_run.py:_on_init():2183] got version response 
2023-07-14 05:10:01,783 INFO    MainThread:56851 [wandb_init.py:init():781] starting run threads in backend
2023-07-14 05:10:01,874 ERROR   MainThread:56851 [wandb_init.py:init():1165] 'ttlDurationSeconds'
Traceback (most recent call last):
  File "/Users/estellaxin/Projects/wandb/wandb/apis/normalize.py", line 41, in wrapper
    return func(*args, **kwargs)
  File "/Users/estellaxin/Projects/wandb/wandb/apis/public.py", line 926, in artifact
    artifact = wandb.Artifact._from_name(
  File "/Users/estellaxin/Projects/wandb/wandb/sdk/artifacts/artifact.py", line 292, in _from_name
    return cls._from_attrs(entity, project, name, attrs, client)
  File "/Users/estellaxin/Projects/wandb/wandb/sdk/artifacts/artifact.py", line 333, in _from_attrs
    artifact._ttl_duration_seconds = attrs["ttlDurationSeconds"]
KeyError: 'ttlDurationSeconds'

During handling of the above exception, another exception occurred:

Traceback (most recent call last):
  File "/Users/estellaxin/Projects/wandb/wandb/sdk/wandb_init.py", line 1147, in init
    run = wi.init()
  File "/Users/estellaxin/Projects/wandb/wandb/sdk/wandb_init.py", line 811, in init
    run.config.update({k: v}, allow_val_change=True)
  File "/Users/estellaxin/Projects/wandb/wandb/sdk/wandb_config.py", line 184, in update
    sanitized = self._update(d, allow_val_change)
  File "/Users/estellaxin/Projects/wandb/wandb/sdk/wandb_config.py", line 177, in _update
    sanitized = self._sanitize_dict(
  File "/Users/estellaxin/Projects/wandb/wandb/sdk/wandb_config.py", line 237, in _sanitize_dict
    k, v = self._sanitize(k, v, allow_val_change)
  File "/Users/estellaxin/Projects/wandb/wandb/sdk/wandb_config.py", line 252, in _sanitize
    val = self._artifact_callback(key, val)
  File "/Users/estellaxin/Projects/wandb/wandb/sdk/wandb_run.py", line 1310, in _config_artifact_callback
    artifact = public_api.artifact(name=artifact_string)
  File "/Users/estellaxin/Projects/wandb/wandb/apis/normalize.py", line 87, in wrapper
    raise CommError(message, err).with_traceback(sys.exc_info()[2])
  File "/Users/estellaxin/Projects/wandb/wandb/apis/normalize.py", line 41, in wrapper
    return func(*args, **kwargs)
  File "/Users/estellaxin/Projects/wandb/wandb/apis/public.py", line 926, in artifact
    artifact = wandb.Artifact._from_name(
  File "/Users/estellaxin/Projects/wandb/wandb/sdk/artifacts/artifact.py", line 292, in _from_name
    return cls._from_attrs(entity, project, name, attrs, client)
  File "/Users/estellaxin/Projects/wandb/wandb/sdk/artifacts/artifact.py", line 333, in _from_attrs
    artifact._ttl_duration_seconds = attrs["ttlDurationSeconds"]
wandb.errors.CommError: 'ttlDurationSeconds'
